<?xml version="1.0" encoding="utf-8"?>
<!-- Simple cart-pole (inverted pendulum) for simforge sample assets -->
<robot name="cart_pole">

  <!-- Fixed world link -->
  <link name="world"/>

  <!-- Cart: slides along the x-axis -->
  <link name="cart">
    <visual>
      <geometry>
        <box size="0.4 0.2 0.1"/>
      </geometry>
    </visual>
    <collision>
      <geometry>
        <box size="0.4 0.2 0.1"/>
      </geometry>
    </collision>
    <inertial>
      <mass value="1.0"/>
      <inertia ixx="0.0043" ixy="0" ixz="0"
               iyy="0.0141" iyz="0"
               izz="0.0167"/>
    </inertial>
  </link>

  <joint name="slider" type="prismatic">
    <parent link="world"/>
    <child link="cart"/>
    <axis xyz="1 0 0"/>
    <limit lower="-2.4" upper="2.4" effort="100" velocity="10"/>
  </joint>

  <!-- Pole: hinged on top of the cart -->
  <link name="pole">
    <visual>
      <origin xyz="0 0 0.25"/>
      <geometry>
        <cylinder radius="0.02" length="0.5"/>
      </geometry>
    </visual>
    <collision>
      <origin xyz="0 0 0.25"/>
      <geometry>
        <cylinder radius="0.02" length="0.5"/>
      </geometry>
    </collision>
    <inertial>
      <origin xyz="0 0 0.25"/>
      <mass value="0.1"/>
      <inertia ixx="0.0021" ixy="0" ixz="0"
               iyy="0.0021" iyz="0"
               izz="0.000004"/>
    </inertial>
  </link>

  <joint name="hinge" type="revolute">
    <parent link="cart"/>
    <child link="pole"/>
    <origin xyz="0 0 0.05"/>
    <axis xyz="0 1 0"/>
    <limit lower="-1.57" upper="1.57" effort="0" velocity="100"/>
  </joint>

</robot>
